Workbook

Sheet Huong dan su dung
A3: STT | B3: Tên Sheet | C3: Hướng dẫn
A4: 1 | B4: Master List | C4: Nhập đầy đủ thông tin các cột
A5: =A4+1 -> 2 | B5: Nghỉ việc | C5: Cắt danh sách nghỉ việc từ sheet Master List và nhập Ngày nghỉ việc + Lý do nghỉ việc
A6: =A5+1 -> 3 | B6: Theo dõi diêng HĐTV
A7: =A6+1 -> 4 | B7: Lấy số HĐTV và mã nhân viên cho nhân sự mới | C7: Điền đầy đủ các cột, mã số nhân viên lấy số tiếp theo
A8: =A7+1 -> 5 | B8: Lấy số HĐLĐ | C8: Điền đầy đủ các cột
A9: =A8+1 -> 6 | B9: Danh mục HĐLĐ | C9: Thống kê HĐLĐ từng năm

Sheet Master List
A1: 1 | B1: =A1+1 -> 2 | C1: =B1+1 -> 3 | D1: =C1+1 -> 4 | E1: =D1+1 -> 5 | F1: =E1+1 -> 6 | G1: =F1+1 -> 7 | H1: =G1+1 -> 8 | I1: =H1+1 -> 9 | ... BE1: =BD1+1 -> 57 | BG1: =BF1+1 -> 1
A2: Stt | B2: Mã số | C2: Họ và tên Nhân viên | D2: Giới tính | E2: Ngày sinh | F2: Tháng sinh nhật | G2: CCCD | H2: Ngày cấp CCCD | I2: Nơi cấp CCCD | J2: Địa chỉ thường trú (ghi theo CCCD) | K2: Số nhà/ Đường (nơi ở hiện tại) | L2: Phường/ Xã (nơi ở hiện tại) | M2: Quận/ Huyện (nơi ở hiện tại) | N2: Thành phố/ Tỉnh (nơi ở hiện tại) | O2: Số điện thoại liên lạc | P2: Tình trạng hôn nhân | Q2: Họ tên người liên hệ khẩn cấp | R2: Mối quan hệ | S2: Số điện thoại người thân | T2: Nghề nghiệp | U2: Vị trí | V2: Cấp bậc | W2: Phòng ban | X2: Quản lý trực tiếp | Y2: Bằng cấp chuyên môn/ Trình độ văn hóa cao nhất | Z2: Chuyên ngành | AA2: Địa chỉ email (nếu có) | AB2: Ngày thử việc | AC2: Ngày nhận việc chính thức | AD2: Ngày ký hợp đồng | AE2: Thâm niên làm việc | AF2: Tháng đóng BHXH | AG2: Số HĐLĐ cũ | AH2: Trạng thái HĐ | AI2: Ngày ký HĐTV | AJ2: Ngày kết thúc HĐTV | AK2: Ngày ký HĐLĐ XĐTH Lần 1 | AL2: Ngày kết thúc HĐLĐ XĐTH Lần 1 | AM2: Ngày ký HĐLĐ XĐTH Lần 2 | AN2: Ngày kết thúc HĐLĐ XĐTH Lần 2 | AO2: Ngày ký HĐLĐ KXĐTH | AP2: Số sổ BHXH | AQ2: Mức đóng BHXH trên HĐLĐ cũ | AR2: Mức đóng BHXH Từ ngày …./.../…. | AS2: STK cá nhân | AT2: Ghi chú | AU2: Mức lương gross Thử việc | AV2: Mức lương gross Chính thức | AW2: Phụ cấp (nếu có) | AX2: Mức lương điều chỉnh tăng lần 1 | AY2: Ngày hiệu lực | AZ2: Mức lương điều chỉnh tăng lần 2 | BA2: Ngày hiệu lực | BB2: Mức lương điều chỉnh tăng lần 3 | BC2: Ngày hiệu lực | BD2: Mức lương gross hiện tại | BE2: Ngày hiệu lực | BF2: =TODAY() -> 46230 | BG2: Số HĐLĐ mới nhất
A3: =SUBTOTAL(3,$C$3:C3) -> 1 | B3: MS00001 | C3: Phạm Hoàng Anh | D3: Nam | E3: 28140 | F3: =MONTH(E3) -> 1 | G3: 086077004305 | H3: 10/05/2021 | I3: CTCCSQLHCVTTXH | J3: 22A Vũ Ngọc Phan, P. 13, Q. Bình Thạnh, TP. HCM | K3: 22A Vũ Ngọc Phan | L3: 13 | M3: Bình Thạnh | N3: Hồ Chí Minh | O3: 0968888878, 0913148259 | U3: Chủ tịch Hội đồng quản trị | V3: QL Bậc 1 | W3: Chủ tịch Hội đồng quản trị | Y3: Thạc sĩ | AB3: 40311 | AC3: 40360 | AD3: 40360 | AE3: =DATEDIF(AC3,$BF$2,"y") -> 16 | AF3: =VLOOKUP(C3,'[1]T03.2024'!$B$8:$O$58,14,0) -> T07/2010 | AH3: CT | AP3: 0205105429 | AQ3: 7100000
A4: =SUBTOTAL(3,$C$3:C4) -> 2 | B4: MS00002 | C4: Phạm Hoàng Em | D4: Nam | E4: 28990 | F4: =MONTH(E4) -> 5 | G4: 079079021883 | H4: 10/07/2021 | I4: CTCCSQLHCVTTXH | J4: 15/83/107 Võ Duy Ninh, P.22, Q. Bình Thạnh, TP.HCM | K4: 56/25 đường số 4 | L4: Hiệp Bình Chánh | M4: Tp. Thủ Đức | N4: Hồ Chí Minh | O4: 0914353320 | Q4: Lê Thị Thúy | R4: Vợ | S4: 0914353320 | T4: Thạc sĩ kinh tế | U4: Tổng Giám đốc | V4: QL Bậc 2 | W4: Ban Giám Đốc | X4: Trần Thị Thi | Y4: Thạc sĩ kinh tế (QTKD) | AA4: hoangpham15051979@gmail.com | AB4: 46113 | AC4: 46113 | AD4: 46113 | AE4: =DATEDIF(AC4,$BF$2,"y") -> 0 | AF4: T04/2026 | AG4: 05/HĐLĐ/2026/TP | AH4: CT | AP4: 0205105425 | AQ4: 5682000 | BG4: 4
A5: =SUBTOTAL(3,$C$3:C5) -> 3 | B5: MS00003 | C5: Nguyễn Hiếu Thiện | D5: Nam | E5: 26451 | F5: =MONTH(E5) -> 6 | G5: 079072004383 | H5: 22/12/2021 | I5: CTCCSQLHCVTTXH | J5: 78/21/52, Đường số 11, P.11, Gò Vấp, TP HCM | K5: 78/21/52, Đường số 11 | L5: Phường 11 | M5: Gò Vấp | N5: Hồ Chí Minh | O5: 0914303825 | Q5: Lê Thị Xuân Mai | R5: Vợ | S5: 0909591266 | T5: Kỹ sư xây dựng | U5: Phó Tổng Giám đốc | V5: QL Bậc 2 | W5: Ban Giám Đốc | X5: Phạm Hoàng Em | Y5: Kỹ sư xây dựng | AA5: nguyenhieuthien72@gmail.com | AB5: 43330 | AC5: 43330 | AD5: 43330 | AE5: =DATEDIF(AC5,$BF$2,"y") -> 7 | AF5: =VLOOKUP(C5,'[1]T03.2024'!$B$8:$O$58,14,0) -> T09/2018 | AG5: 03/HĐLĐ/2018/TP | AH5: CT | AP5: 0203097816 | AQ5: 5682000 | BG5: 5
A6: =SUBTOTAL(3,$C$3:C6) -> 4 | B6: MS00064 | C6: Nguyễn Bảo Ngọc | D6: Nữ | E6: 34539 | F6: =MONTH(E6) -> 7 | G6: 079194022415 | H6: 09/08/2021 | I6: CTCCSQLHCVTTXH | J6: 56/36/13, Đường số 4, Khu phố 2, Hiệp Bình Chánh, TP Thủ Đức | K6: 56/36/13 đường số 4 | L6: Hiệp Bình Chánh | M6: Thủ Đức | N6: Thủ Đức | O6: 0764969379 | Q6: Tạ Ngọc Hoàng Quân | R6: Chổng | S6: 0988990033 | T6: Hành chính - Nhân sự | U6: Nhân viên Hành Chính Nhân Sự | V6: Nhân viên | W6: Hành chính - Nhân sự | X6: Trần Thị Thi | Y6: Cử nhân tài chính doanh nghiệp | AA6: ngocnb2407@gmail.com | AB6: 44341 | AC6: 44504 | AD6: 44504 | AE6: =DATEDIF(AC6,$BF$2,"y") -> 4 | AF6: =VLOOKUP(C6,'[1]T03.2024'!$B$8:$O$58,14,0) -> T11/2021 | AG6: 05/HĐLĐ/2021/TP | AH6: CT | AP6: 7916450461 | AQ6: 5682000 | BG6: 6
A7: =SUBTOTAL(3,$C$3:C7) -> 5 | B7: MS00027 | C7: Huỳnh Văn Lũy | D7: Nam | E7: 29754 | F7: =MONTH(E7) -> 6 | G7: 046081003631 | H7: 27/12/2021 | I7: CTCCSQLHCVTTXH | J7: Phú Thuận ,Phú Vang , Thừa Thiên Huế | K7: 108/7 đường số 1 | L7: 16 | M7: Gò Vấp | N7: Hồ Chí Minh | O7: 0389636252 | Q7: Nguyễn Thị Thương | R7: Vợ | S7: 0937191886 | T7: Tài xế | U7: Tài xế văn phòng | V7: Nhân viên | W7: Hành chính - Nhân sự | X7: Trần Thị Thi | Y7: 12/12 | AA7: Thanhlong111@icloud.com | AB7: 41192 | AC7: 41192 | AD7: 41365 | AE7: =DATEDIF(AC7,$BF$2,"y") -> 13 | AF7: =VLOOKUP(C7,'[1]T03.2024'!$B$8:$O$58,14,0) -> T04/2013 | AG7: 01/HĐLĐ/2013/TP | AH7: CT | AP7: 7913037584 | AQ7: 5682000 | BG7: 7
A8: =SUBTOTAL(3,$C$3:C8) -> 6 | B8: MS00028 | C8: Đồng Văn Thạch | D8: Nam | E8: 27030 | F8: =MONTH(E8) -> 1 | G8: 072074011985 | H8: 27/12/2021 | I8: CTCCSQLHCVTTXH | J8: Trường Phương, Trường Tây, Hoa Thành, Tây Ninh | K8: 1/21H đường 53 | L8: Phương Hiệp Bình Chánh | M8: Tp. Thủ Đức | N8: Hồ Chí Minh | O8: 0988142133 | Q8: Phạm Thị Mỹ Dung | R8: Vợ | S8: 0904896619 | T8: Tài xế | U8: Tài xế văn phòng | V8: Nhân viên | W8: Hành chính - Nhân sự | X8: Trần Thị Thi | Y8: 5/12 | AA8: dongvanthach010174@gmail.com | AB8: 43739 | AC8: 43739 | AD8: 43770 | AE8: =DATEDIF(AC8,$BF$2,"y") -> 6 | AF8: =VLOOKUP(C8,'[1]T03.2024'!$B$8:$O$58,14,0) -> T11/2019 | AG8: 25/HĐLĐ/2019/TP | AH8: CT | AP8: 0205357705 | AQ8: 5682000 | BG8: 8
A9: =SUBTOTAL(3,$C$3:C9) -> 7 | B9: MS00031 | C9: Trần Văn Khình | D9: Nam | E9: 30944 | F9: =MONTH(E9) -> 9 | G9: 089084018012 | H9: 44845 | I9: CTCCSQLHCVTTXH | J9: Tổ 9, Ấp 2 Vĩnh Xương, thị xã Tân Châu, An Giang | K9: 22A Vũ Ngọc Phan | L9: 13 | M9: Bình Thạnh | N9: Hồ Chí Minh | O9: 0925578743 | Q9: Nguyễn Thị Phương | R9: Vợ | S9: 0394716626 | T9: Bảo vệ | U9: Bảo vệ | V9: Nhân viên | W9: Hành chính - Nhân sự | X9: Trần Thị Thi | Y9: không có | AB9: 43899 | AC9: 43960 | AD9: 44564 | AE9: =DATEDIF(AC9,$BF$2,"y") -> 6 | AF9: =VLOOKUP(C9,'[1]T03.2024'!$B$8:$O$58,14,0) -> T01/2022 | AG9: 03/HĐLĐ/2022/TP | AH9: CT | AP9: 8922834930 | AQ9: 5682000 | BG9: 9
A10: =SUBTOTAL(3,$C$3:C10) -> 8 | B10: MS00021 | C10: Võ Thị Muội | D10: Nữ | E10: 28756 | F10: =MONTH(E10) -> 9 | G10: 087178001172 | H10: 02/04/2021 | I10: CTCCSQLHCVTTXH | J10: Tổ 15, Ấp Trà Đư, Thường Lạc, Hồng Ngự, Đồng Tháp | K10: 22A Vũ Ngọc Phan | L10: 13 | M10: Bình Thạnh | N10: Hồ Chí Minh | O10: 0907377749 | T10: Kế toán | U10: Thành viên hội đồng quản trị | V10: Nhân viên | W10: Tài chính - Kế toán | X10: Phạm Hoàng Em | Y10: Đại học | AB10: 40422 | AC10: 40422 | AD10: 40422 | AE10: =DATEDIF(AC10,$BF$2,"y") -> 15 | AF10: =VLOOKUP(C10,'[1]T03.2024'!$B$8:$O$58,14,0) -> T09/2010 | AG10: 01/HĐLĐ/2010/TP | AH10: CT | AP10: 7910430254 | AQ10: 5682000 | BG10: 10
A11: =SUBTOTAL(3,$C$3:C11) -> 9 | B11: MS00063 | C11: Đặng Hà Đoan Dung | D11: Nữ | E11: 31273 | F11: =MONTH(E11) -> 8 | G11: 056185003113 | H11: 20/12/2021 | I11: CTCCSQLHCVTTXH | J11: 58/17 E, Trương Văn Thành, P. Hiệp Phú. Q.9 | K11: 3/58F, Đường 182 | L11: Phường Tăng Nhơn Phú A | M11: 9 | N11: Hồ Chí Minh | O11: 0933864646 | Q11: Đặng Đức Cường | R11: Chổng | S11: 0973126162 | T11: Kế toán | U11: Nhân viên kế toán | V11: Nhân viên | W11: Tài chính - Kế toán | X11: Lê Mĩ Dung | Y11: Cử nhân tài chính ngân hàng | AA11: dh_doandung@yahoo.com | AB11: 42079 | AC11: 42079 | AD11: 42461 | AE11: =DATEDIF(AC11,$BF$2,"y") -> 11 | AF11: =VLOOKUP(C11,'[1]T03.2024'!$B$8:$O$58,14,0) -> T04/2016 | AG11: 02/HĐLĐ/2016/TP | AH11: CT | AP11: 7909247191 | AQ11: 5682000 | BG11: 11
A12: =SUBTOTAL(3,$C$3:C12) -> 10 | B12: MS00023 | C12: Huỳnh Thị Nhiên | D12: Nữ | E12: 30399 | F12: =MONTH(E12) -> 3 | G12: 083183019670 | H12: 10/07/2021 | I12: CTCCSQLHCVTTXH | J12: 51 Đường 6, P An Khánh, TP Thủ Đức, HCM | K12: 51 Đường 6 | L12: P An Khánh | M12: Tp. Thủ Đức | N12: Hồ Chí Minh | O12: 0907275123 | Q12: Ngô Phú Diễn | R12: Chồng | S12: 0909994134 | T12: Kế toán | U12: Nhân viên kế toán | V12: Nhân viên | W12: Tài chính - Kế toán | X12: Lê Mĩ Dung | Y12: Cử nhân ngành kế toán | AA12: huynhnhienbt@gmail.com | AB12: 43314 | AC12: 43374 | AD12: 44743 | AE12: =DATEDIF(AC12,$BF$2,"y") -> 7 | AF12: T07/2022 | AG12: 02/HĐLĐ/2020/PĐ | AH12: CT | AP12: 0206001901 | AQ12: 5682000 | AT12: Phú Đức | BG12: 12
A13: =SUBTOTAL(3,$C$3:C13) -> 11 | B13: MS00008 | C13: Nguyễn Thành Trung | D13: Nam | E13: 30376 | F13: =MONTH(E13) -> 3 | G13: 049083000048 | H13: 22/12/2021 | I13: CTCCSQLHCVTTXH | J13: 137 Nguyễn Xí, Phường 26, Bình Thạnh, TP. HCM | K13: 520/111/3 Quốc lộ 13; Khu phố 6 | L13: Hiệp Bình Phước | M13: Tp. Thủ Đức | N13: Hồ Chí Minh | O13: 0909711588 | Q13: Phạm Thị Hà Nguyên | R13: Vợ | S13: 0908732975 | T13: Kỹ sư xây dựng cầu đường bộ | U13: Trợ lý Chủ tịch HĐQT | V13: QL Bậc 3 | W13: Kỹ thuật - Thi công | X13: Phạm Hoàng Anh | Y13: Kỹ sư xây dựng Cầu Đường Bộ | AA13: thanhtrung_625@yahoo.com.vn | AB13: 43678 | AC13: 43709 | AD13: 43739 | AE13: =DATEDIF(AC13,$BF$2,"y") -> 6 | AF13: =VLOOKUP(C13,'[1]T03.2024'!$B$8:$O$58,14,0) -> T10/2019 | AG13: 10/HĐLĐ/2019/TP | AH13: CT | AP13: 0206313215 | AQ13: 5682000 | BG13: 13
A14: =SUBTOTAL(3,$C$3:C14) -> 12 | B14: MS00010 | C14: Nguyễn Thành Nhân | D14: Nam | E14: 33626 | F14: =MONTH(E14) -> 1 | G14: 058092008735 | H14: 16/01/2022 | I14: CTCCSQLHCVTTXH | J14: KP5, P. Phủ Hà, Phan Rang-Tháp Chàm, Ninh Thuận | K14: 91/43 Nguyên Hồng | L14: Phường 1 | M14: Gò Vấp | N14: Hồ Chí Minh | O14: 0796695039 | Q14: Nguyễn Thị Ánh Tuyết | R14: Vơ | S14: 0909258751 | T14: Kỹ sư xây dựng | U14: Trưởng bộ phận QA/ QC/ QS | V14: QL Bậc 4 | W14: Kỹ thuật - Thi công | X14: Nguyễn Hiếu Thiện | Y14: Kỹ sư xây dựng | AA14: ksnhan.ou@gmail.com | AB14: 42081 | AC14: 42081 | AD14: 42461 | AE14: =DATEDIF(AC14,$BF$2,"y") -> 11 | AF14: =VLOOKUP(C14,'[1]T03.2024'!$B$8:$O$58,14,0) -> T04/2016 | AG14: 03/HĐLĐ/2016/TP | AH14: CT | AP14: 7916037564 | AQ14: 5682000 | BG14: 14
A15: =SUBTOTAL(3,$C$3:C15) -> 13 | B15: MS00019 | C15: Phan Vũ Thịnh | D15: Nam | E15: 32150 | F15: =MONTH(E15) -> 1 | G15: 086088011754 | H15: 44711 | I15: CTCCSQLHCVTTXH | J15: 15A/1 Khóm 2 thị trấn Long Hồ, huyện Long Hồ, tỉnh Vĩnh Long | K15: 232/1/32 Bình Lợi | L15: Phường 13 | M15: Bình Thạnh | N15: Hồ Chí Minh | O15: 0914549944 | Q15: Lê Quốc Chánh | R15: Anh | S15: 0988322584 | T15: Kỹ sư xây dựng | U15: Cán bộ QA/ QC/ QS | V15: Nhân viên | W15: Kỹ thuật - Thi công | X15: Phạm Hồng Nhiên | Y15: Kỹ sư xây dựng | AA15: vuthinh2019@gmail.com | AB15: 43598 | AC15: 43617 | AD15: 43862 | AE15: =DATEDIF(AC15,$BF$2,"y") -> 7 | AF15: =VLOOKUP(C15,'[1]T03.2024'!$B$8:$O$58,14,0) -> T02/2020 | AG15: 01/HĐLĐ/2020/TP | AH15: CT | AP15: 7913036175 | AQ15: 5682000 | BG15: 15
A16: =SUBTOTAL(3,$C$3:C16) -> 14 | B16: MS00050 | C16: Lê Minh Hoàng | D16: Nam | E16: 32235 | F16: =MONTH(E16) -> 4 | G16: 052088009432 | H16: 13/01/2022 | I16: CTCCSQLHCVTTXH | J16: Kỳ Sơn-Phước Sơn-Tuy Phước-Bình Định | K16: 323/20D-Đường Tỉnh lộ 15-Ấp Phú An | L16: Phú Hòa Đông | M16: Củ Chi | N16: Hồ Chí Minh | O16: 0982543268, 0932415363 | Q16: Lê Minh Vũ | R16: Người nhà | S16: 0935841468 | T16: Kỹ sư xây dựng cầu đường | U16: Cán bộ kỹ thuật | V16: Nhân viên | W16: Kỹ thuật - Thi công | X16: Nguyễn Thành Trung (0909711588, 0901394013) | Y16: Kỹ sư xây dựng cầu đường | AA16: leminhps@gmail.com | AB16: 44326 | AC16: 44326 | AD16: 44347 | AE16: =DATEDIF(AC16,$BF$2,"y") -> 5 | AF16: =VLOOKUP(C16,'[1]T03.2024'!$B$8:$O$58,14,0) -> T06/2021 | AG16: 01/HĐLĐ/2021/TP | AH16: CT | AP16: 5221303235 | AQ16: 5682000 | BG16: 16
A17: =SUBTOTAL(3,$C$3:C17) -> 15 | B17: MS00016 | C17: Huỳnh Ngọc Hùng | D17: Nam | E17: 32157 | F17: =MONTH(E17) -> 1 | G17: 086088002381 | H17: 45033 | I17: CTCCSQLHCVTTXH | J17: Ấp Tường Nhơn, xã Tường Lộc, Tam Bình, Vĩnh Long | K17: 22/6 Tân Thuận Tây | L17: Tân Thuận Tây | M17: 7 | N17: Hồ Chí Minh | O17: 0916026056 | Q17: Đặng Thị My | R17: Vợ | S17: 0365146510 | T17: Điện công nghiệp và dân dụng | U17: Cán bộ kỹ thuật M&E | V17: Nhân viên | W17: Kỹ thuật - Thi công | X17: Nguyễn Ngọc Phi Hổ | Y17: Cao Đẳng điện công nghiệp và dân dụng | AA17: huynhngochung1501@gmail.com | AB17: 43693 | AC17: 43693 | AD17: 43891 | AE17: =DATEDIF(AC17,$BF$2,"y") -> 6 | AF17: =VLOOKUP(C17,'[1]T03.2024'!$B$8:$O$58,14,0) -> T03/2020 | AG17: 08/HĐLĐ/2020/TP | AH17: CT | AP17: 7413215969 | AQ17: 5682000 | BG17: 17
A18: =SUBTOTAL(3,$C$3:C18) -> 16 | B18: MS00033 | C18: Nguyễn Văn Trường | D18: Nam | E18: 33336 | F18: =MONTH(E18) -> 4 | G18: 038091013623 | H18: 44798 | I18: CTCCSQLHCVTTXH | J18: 361/70/89a ấp 6 , Đông Thạnh, Hóc Môn, Hcm | K18: Tổ 49, ấp Thới Tứ | L18: Thới Tam Thôn | M18: Hóc Môn | N18: Hồ Chí Minh | O18: 0919193368 | Q18: Trần Thu Thủy | R18: Vợ | S18: 0932775188 | T18: Kỹ sư kinh tế xây dựng | U18: TBP nhôm kính | V18: Nhân viên | W18: Kỹ thuật - Thi công | X18: Nguyễn Minh Hiếu | Y18: Kỹ sư | AA18: Truongnvktxd@gmail.com | AB18: 44004 | AC18: 44005 | AD18: 44075 | AE18: =DATEDIF(AC18,$BF$2,"y") -> 6 | AF18: =VLOOKUP(C18,'[1]T03.2024'!$B$8:$O$58,14,0) -> T09/2020 | AG18: 17/HĐLĐ/2020/TP | AH18: CT | AP18: 7915035064 | AQ18: 5682000 | BG18: 18
A19: =SUBTOTAL(3,$C$3:C19) -> 17 | B19: MS00014 | C19: Nguyễn Ngọc Phi Hổ | D19: Nam | E19: 29306 | F19: =MONTH(E19) -> 3 | G19: 056080003320 | H19: 24/06/2022 | I19: CTCCSQLHCVTTXH | J19: 63/1 Xóm Cồn, phường Xương Huân, Tp Nha Trang, tỉnh Khánh Hòa | K19: 361/14/23C Bình Đông | L19: Phường 15 | M19: Quận 8 | N19: Hồ Chí Minh | O19: 0905202687 | Q19: Quách Tố Thanh | R19: Vợ | S19: 0909448038 | T19: Kỹ sư điện | U19: Trưởng bộ phận M&E | V19: QL Bậc 4 | W19: Kỹ thuật - Thi công | X19: Nguyễn Minh Hiếu | Y19: Kỹ sư điện | AA19: honguyen260380@gmail.com | AB19: 41395 | AC19: 41395 | AD19: 42795 | AE19: =DATEDIF(AC19,$BF$2,"y") -> 13 | AF19: =VLOOKUP(C19,'[1]T03.2024'!$B$8:$O$58,14,0) -> T03/2017 | AG19: 02/HĐLĐ/2017/TP | AH19: CT | AP19: 7908055913 | AQ19: 5682000 | BG19: 19
A20: =SUBTOTAL(3,$C$3:C20) -> 18 | B20: MS00059 | C20: Nguyễn Quốc Trị | D20: Nam | E20: 29901 | F20: =MONTH(E20) -> 11 | G20: 052081010885 | H20: 19/02/2022 | I20: CTCCSQLHCVTTXH | J20: Phước Hưng, Tuy Phước, Bình Định | K20: 269b Nguyễn Thái Học | L20: Phường Mỹ Hòa | M20: Tp. Long xuyên | N20: Tỉnh An Giang | O20: 0933887426 | Q20: Nguyển Thị Thu Thủy | R20: Mẹ | S20: 0966483549 | T20: Xây dựng | U20: Cán bộ kỹ thuật | V20: Nhân viên | W20: Kỹ thuật - Thi công | X20: Âu Văn Vũ | Y20: Trung cấp xây dựng | AA20: Quoctrixdtd@gmail.com | AB20: 44007 | AC20: 44007 | AD20: 44075 | AE20: =DATEDIF(AC20,$BF$2,"y") -> 6 | AF20: =VLOOKUP(C20,'[1]T03.2024'!$B$8:$O$58,14,0) -> T09/2020 | AG20: 20/HĐLĐ/2020/TP | AH20: CT | AP20: 5221269029 | AQ20: 5682000 | BG20: 20
A21: =SUBTOTAL(3,$C$3:C21) -> 19 | B21: MS00060 | C21: Phan Phú Trường | D21: Nam | E21: 25329 | F21: =MONTH(E21) -> 5 | G21: 086069008859 | H21: 30/06/2022 | I21: CTCCSQLHCVTTXH | J21: Ấp 8-Mỹ Lộc-Tam Bình-Vĩnh Long | K21: 323/20D-Đường Tỉnh Lộ 15-Ấp Phú An | L21: Phú Hòa Đông | M21: Củ Chi | N21: Hồ Chí Minh | O21: 0933170366 | Q21: Luyến | R21: Anh | S21: 0965325539 | T21: Tài xế | U21: Tài xế | V21: Nhân viên | W21: Vật tư - Thiết bị | X21: Dương Thái Luyến | Y21: Bằng lái cẩu tháp | AA21: Không | AB21: 43983 | AC21: 43983 | AD21: 44564 | AE21: =DATEDIF(AC21,$BF$2,"y") -> 6 | AF21: =VLOOKUP(C21,'[1]T03.2024'!$B$8:$O$58,14,0) -> T01/2022 | AG21: 05/HĐLĐ/2022/TP | AH21: CT | AP21: 8622459133 | AQ21: 5682000 | BG21: 22
A22: =SUBTOTAL(3,$C$3:C22) -> 20 | B22: MS00052 | C22: Nguyễn Văn Pha | D22: Nam | E22: 29221 | F22: =MONTH(E22) -> 1 | G22: 086080012613 | H22: 25/02/2022 | I22: CTCCSQLHCVTTXH | J22: Phú Sơn C-Long Phú-Tam Bình-Vĩnh Long | K22: 323/20D-Đường Tỉnh Lộ 15-Ấp Phú An | L22: Phú Hòa Đông | M22: Củ Chi | N22: Hồ Chí Minh | O22: 0899675705 | Q22: Luyến | R22: Anh | S22: 0965325539 | T22: Tài xế | U22: Tài xế | V22: Nhân viên | W22: Vật tư - Thiết bị | X22: Dương Thái Luyến | Y22: Không | AA22: Không | AB22: 43983 | AC22: 43983 | AD22: 44564 | AE22: =DATEDIF(AC22,$BF$2,"y") -> 6 | AF22: =VLOOKUP(C22,'[1]T03.2024'!$B$8:$O$58,14,0) -> T01/2022 | AG22: 04/HĐLĐ/2022/TP | AH22: CT | AP22: 8621765075 | AQ22: 5682000 | BG22: 23
A23: =SUBTOTAL(3,$C$3:C23) -> 21 | B23: MS00007 | C23: Dương Huỳnh Tâm Quyên | D23: Nữ | E23: 31247 | F23: =MONTH(E23) -> 7 | G23: 094185007086 | H23: 12/08/2021 | I23: CTCCSQLHCVTTXH | J23: Tổ 16, KP2, Phú Bình, TP. Long Khánh, Đồng Nai | K23: 294 Bình Lợi | L23: P 13 | M23: Bình Thạnh | N23: Hồ Chí Minh | O23: 0909063985 | R23: Người nhà | S23: 0937204379 | U23: Nhân viên vật tư | V23: Nhân viên | W23: Vật tư - Thiết bị | X23: Lê Thị Thúy | Y23: Cao đẳng sư phạm | AA23: tamquyen1985@gmail.com | AB23: 43992 | AC23: 43992 | AD23: 44835 | AE23: =DATEDIF(AC23,$BF$2,"y") -> 6 | AF23: T10/2022 | AG23: 03/HĐLĐ/2020/PĐ | AH23: CT | AP23: 0205260269 | AQ23: 5682000 | AT23: Phú Đức | BG23: 24
A24: =SUBTOTAL(3,$C$3:C24) -> 22 | B24: MS00004 | C24: Dương Thái Luyến | D24: Nam | E24: 32428 | F24: =MONTH(E24) -> 10 | G24: 091088013166 | H24: 44928 | I24: CTCCSQLHCVTTXH | J24: ấp Vĩnh Phong, Vĩnh Tuy, Gò Quao, Kiên Giang | K24: 323/20D-Đường Tỉnh Lộ 15-Ấp Phú An | L24: Phú Hòa Đông | M24: Củ Chi | N24: Hồ Chí Minh | O24: 0914725539 | Q24: Nguyễn Trường An | R24: Vợ | S24: 0949320714 | U24: Nhân viên thiết bị | V24: Nhân viên | W24: Vật tư - Thiết bị | X24: Cao Thanh Long | Y24: Không | AA24: luyenduongxd1210@gmail.com | AB24: 41426 | AC24: 41426 | AD24: 42639 | AE24: =DATEDIF(AC24,$BF$2,"y") -> 13 | AF24: =VLOOKUP(C24,'[1]T03.2024'!$B$8:$O$58,14,0) -> T10/2016 | AG24: 20/HĐLĐ/2016/TP | AH24: CT | AP24: 7916264390 | AQ24: 5682000 | BG24: 25
A25: =SUBTOTAL(3,$C$3:C25) -> 23 | B25: MS00006 | C25: Nguyễn Hoa Linh | D25: Nữ | E25: 32880 | F25: =MONTH(E25) -> 1 | G25: 080190014391 | H25: 04/02/2022 | I25: CTCCSQLHCVTTXH | J25: Ấp An Thuỷ, An Ninh Tây, Đức Hoà, Long An | K25: 177/1 Duyên Hải, Kp Hưng Thạnh | L25: Tt cần Thạnh | M25: Cần Giờ | N25: Hồ Chí Minh | O25: 0909135746 | R25: Người nhà | S25: 0909809004 | U25: Nhân viên vật tư | V25: Nhân viên | W25: Vật tư - Thiết bị | X25: Lê Thị Thúy | Y25: Đại học | AA25: Nguyenhoalinh90@gmail.com | AB25: 42068 | AC25: 42068 | AD25: 42461 | AE25: =DATEDIF(AC25,$BF$2,"y") -> 11 | AF25: =VLOOKUP(C25,'[1]T03.2024'!$B$8:$O$58,14,0) -> T04/2016 | AG25: 04/HĐLĐ/2016/TP | AH25: CT | AP25: 8214014160 | AQ25: 5682000 | BG25: 26
A26: =SUBTOTAL(3,$C$3:C26) -> 24 | B26: MS00043 | C26: Đoàn Thị Kim Tuyền | D26: Nữ | E26: 32086 | F26: =MONTH(E26) -> 11 | G26: 087187001621 | H26: 02/04/2021 | I26: CTCCSQLHCVTTXH | J26: Ấp 6, Xã Thường Lạc, Huyện hồng Ngự, Tỉnh Đồng Tháp | K26: H323/20D Tỉnh Lộ 15, Ấp Phú An | L26: Xã Phú Hòa Đông | M26: Huyện Củ Chi | N26: Thành Phố Hồ Chí Minh | O26: 0334273918 - 0815833152 | Q26: Đặng Thanh Bình | R26: Chồng | S26: 0396296809 | T26: Thủ kho | U26: Thủ kho | V26: Nhân viên | W26: Vật tư - Thiết bị | X26: Cao Thanh Long | Y26: 5/12 | AA26: doanthikimtuyen6563@gmail.com | AB26: 41640 | AC26: 41640 | AD26: 43922 | AE26: =DATEDIF(AC26,$BF$2,"y") -> 12 | AF26: T04/2020 | AG26: 01/HĐLĐ/2020/PĐ | AH26: CT | AP26: #N/A | AQ26: 5682000 | AT26: Phú Đức | BG26: 29
A27: =SUBTOTAL(3,$C$3:C27) -> 25 | B27: MS00044 | C27: Nguyễn Thanh Nam | D27: Nam | E27: 34993 | F27: =MONTH(E27) -> 10 | G27: 089095019349 | H27: 27/02/2022 | I27: CTCCSQLHCVTTXH | J27: Vĩnh Bường, Vĩnh Hòa, Tân Châu, An Giang | K27: Cục thuế tỉnh An Giang, Nguyễn Thái Học | L27: phường Mỹ Hòa | M27: Tp. Long Xuyên | N27: Tỉnh An Giang | O27: 0919195091 | R27: Người nhà | S27: 0947484993 | T27: Kỹ sư xây dựng | U27: Chỉ huy trưởng | V27: QL Bậc 4 | W27: Kỹ thuật - Thi công | X27: Nguyễn Minh Hiếu | Y27: Kỹ sư xây dựng | AA27: thanhnamnguyen1701@gmail.com | AB27: 42795 | AC27: 43772 | AD27: 45962 | AE27: =DATEDIF(AC27,$BF$2,"y") -> 6 | AF27: T11/2025 | AG27: 19/HĐLĐ/2025/TP | AH27: CT | AP27: 8925158542 | AQ27: 5682000 | AT27: Giảm BHXH từ tháng 01/2024 để nhận BH 1 lần | BG27: 30
A28: =SUBTOTAL(3,$C$3:C28) -> 26 | B28: MS00041 | C28: Huỳnh Long Hồ | D28: Nam | E28: 32874 | F28: =MONTH(E28) -> 1 | G28: 087090017813 | H28: 04/02/2022 | I28: CTCCSQLHCVTTXH | J28: Khóm Trung 2, TT. Thường Thới Tiền, Hồng Ngự, Đồng Tháp | K28: Ấp Bình Lợi | L28: Xã Bình Khánh | M28: Cần Giờ | N28: Hồ Chí Minh | O28: 0916414494 | Q28: Lê Thị Kiều Oanh | R28: Vợ | S28: 0942030339 | T28: Xây dựng | U28: Cán bộ kỹ thuật | V28: Nhân viên | W28: Kỹ thuật - Thi công | X28: Âu Văn Vũ | Y28: Trung cấp xây dựng | AA28: Huynhhodt66@gamil.com | AB28: 42795 | AC28: 42795 | AD28: 42795 | AE28: =DATEDIF(AC28,$BF$2,"y") -> 9 | AF28: =VLOOKUP(C28,'[1]T03.2024'!$B$8:$O$58,14,0) -> T03/2017 | AG28: 01/HĐLĐ/2017/TP | AH28: CT | AP28: 7916455166 | AQ28: 5682000 | BG28: 31
A29: =SUBTOTAL(3,$C$3:C29) -> 27 | B29: MS00038 | C29: Hoàng Tăng Bảo Chánh | D29: Nam | E29: 26076 | F29: =MONTH(E29) -> 5 | G29: 074071009564 | H29: 23/09/2022 | I29: CTCCSQLHCVTTXH | J29: Tổ 3 Ấp 1, Hưng Hòa, Bàu Bàng, Bình Dương | K29: 189 Ấp 1 | L29: Xã Hưng Hòa | M29: Bầu Bàng | N29: Bình Dương | O29: 0918479120 | R29: Người nhà | S29: 0388650778 | T29: Xây dựng | U29: Cán bộ kỹ thuật | V29: Nhân viên | W29: Kỹ thuật - Thi công | X29: Nguyễn Hiếu Thiện | Y29: 12/12 | AA29: hoangtangbaochanh123@gmail.com | AB29: 43452 | AC29: 43452 | AD29: 43452 | AE29: =DATEDIF(AC29,$BF$2,"y") -> 7 | AF29: =VLOOKUP(C29,'[1]T03.2024'!$B$8:$O$58,14,0) -> T01/2019 | AG29: 04/HĐLĐ/2018/TP | AH29: CT | AP29: 0205157361 | AQ29: 5682000 | BG29: 33
A30: =SUBTOTAL(3,$C$3:C30) -> 28 | B30: MS00054 | C30: Âu Văn Vũ | D30: Nam | E30: 32523 | F30: =MONTH(E30) -> 1 | G30: 087089007221 | H30: 19/01/2022 | I30: CTCCSQLHCVTTXH | J30: B5/15, Ấp An Lợi B, Định yên, Lấp vò, Đồng Tháp | K30: B5/15, Ấp An Lợi B, Định yên, Lấp vò, Đồng Tháp | L30: Định Yên | M30: Lấp Vò | N30: Đồng Tháp | O30: 0938678929 | R30: Vợ | S30: 0919562199 | T30: Kỹ sư xây dựng | U30: Chỉ huy trưởng | V30: QL Bậc 4 | W30: Kỹ thuật - Thi công | X30: Nguyễn Minh Hiếu | Y30: Kỹ sư xây dựng | AA30: auvanvu1501@gmail.com | AB30: 43570 | AC30: 43575 | AD30: 43556 | AE30: =DATEDIF(AC30,$BF$2,"y") -> 7 | AF30: =VLOOKUP(C30,'[1]T03.2024'!$B$8:$O$58,14,0) -> T04/2019 | AG30: 11/HĐLĐ/2019/TP | AH30: CT | AP30: 7914162911 | AQ30: 5682000 | BG30: 34
A31: =SUBTOTAL(3,$C$3:C31) -> 29 | B31: MS00049 | C31: Nguyễn Văn Trân | D31: Nam | E31: 18553 | F31: =MONTH(E31) -> 10 | G31: 080050000916 | H31: 20/04/2021 | I31: CTCCSQLHCVTTXH | J31: Ấp Trần Hưng Đạo, Xã Tam Thôn Hiệp, Huyện Cần Giờ, Tp. HCM | K31: Ấp bình lợi | L31: Xã bình khánh | M31: Cần Giờ | N31: Hồ Chí Minh | O31: 0363213558 | Q31: Tô Thị Dẹp | R31: Vợ | S31: 0349738816 | T31: Thủ kho | U31: Thủ kho | V31: Nhân viên | W31: Vật tư - Thiết bị | X31: Dương Thái Luyến | Y31: 12/12 | AA31: không | AB31: 43750 | AC31: 43811 | AD31: 0 | AE31: =DATEDIF(AC31,$BF$2,"y") -> 6 | AH31: CT | AP31: 0 | AT31: Không đóng BHXH | BG31: 35
A32: =SUBTOTAL(3,$C$3:C32) -> 30 | B32: MS00015 | C32: Huỳnh Minh Nghị | D32: Nam | E32: 32303 | F32: =MONTH(E32) -> 6 | G32: 089088007677 | H32: 13/08/2021 | I32: CTCCSQLHCVTTXH | J32: Ấp vĩnh Bình,vĩnh Thạnh Trung,Châu Phú,An Giang | K32: 1/219 kp Hòa Lân 2 | L32: Thuận Giao | M32: Thuận An | N32: Bình Dương | O32: 0937330927 | Q32: Đặng Thị Hồng Lê | R32: Vợ | S32: 0937358737 | T32: Điện | U32: Cán bộ kỹ thuật M&E | V32: Nhân viên | W32: Kỹ thuật - Thi công | X32: Nguyễn Ngọc Phi Hổ | Y32: K có | AA32: minhnghichaudoc@gmail.com | AB32: 44487 | AC32: 44487 | AD32: 44487 | AE32: =DATEDIF(AC32,$BF$2,"y") -> 4 | AF32: =VLOOKUP(C32,'[1]T03.2024'!$B$8:$O$58,14,0) -> T11/2021 | AG32: 03/HĐLĐ/2021/TP | AH32: CT | AP32: 8923267816 | AQ32: 5682000 | BG32: 36
A33: =SUBTOTAL(3,$C$3:C33) -> 31 | B33: MS00065 | C33: Phạm Văn Phụng | D33: Nam | E33: 27395 | F33: =MONTH(E33) -> 1 | G33: 087075007392 | H33: 09/08/2021 | I33: CTCCSQLHCVTTXH | J33: Xã Thường Lạc, Hồng Ngự, Đồng Tháp | K33: 293B | L33: Mỹ Hòa | M33: Tp. Long Xuyên | N33: Tỉnh An Giang | O33: 0339333710 | T33: Bảo vệ | U33: Bảo vệ | V33: Nhân viên | W33: Hành chính - Nhân sự | X33: Nguyễn Thanh Nam | Y33: không có | AA33: không | AB33: 44341 | AC33: 44402 | AD33: 0 | AE33: =DATEDIF(AC33,$BF$2,"y") -> 5 | AH33: CT | AP33: 0 | AT33: Không đóng BHXH | BG33: 37
A34: =SUBTOTAL(3,$C$3:C34) -> 32 | B34: MS00066 | C34: Lê Quốc Dũng | D34: Nam | E34: 28628 | F34: =MONTH(E34) -> 5 | G34: 079078017071 | H34: 19/04/2021 | I34: CTCCSQLHCVTTXH | J34: 18/10 Trần Văn Thành, Phường 8, Quận 8 | K34: 551/333 Lê Văn Khương | L34: Phường thế an | M34: Quận12 | N34: TP HCM | O34: 0934343293 | Q34: Lê Ngọc Sơn | R34: Em | S34: 0978611151 | T34: Thủ kho | U34: Thủ kho | V34: Nhân viên | W34: Vật tư - Thiết bị | X34: Võ Thành Vương | Y34: 12/12 | AA34: lequocdungq@gmail.com | AB34: 44487 | AC34: 44518 | AD34: 03/01/2022 | AE34: =DATEDIF(AC34,$BF$2,"y") -> 4 | AF34: =VLOOKUP(C34,'[1]T03.2024'!$B$8:$O$58,14,0) -> T01/2022 | AG34: 01/HĐLĐ/2022/TP | AH34: CT | AP34: 0204344328 | AQ34: 5682000 | BG34: 38
A35: =SUBTOTAL(3,$C$3:C35) -> 33 | B35: MS00068 | C35: Nguyễn Duy Hải | D35: Nam | E35: 33626 | F35: =MONTH(E35) -> 1 | G35: 082092015182 | H35: 44326 | I35: CTCCSQLHCVTTXH | J35: C9bis, KP 1, Đông Hưng Thuận, Quận 12, Hồ Chí Minh | K35: 91/43 Nguyên Hồng | L35: Phường 1 | M35: Gò Vấp | N35: Hồ Chí Minh | O35: 0984071062 | Q35: Vi | R35: Vợ | S35: 097 2801506 | T35: Kỹ sư xây dựng | U35: Nhân viên Kế hoạch - Đấu thầu | V35: Nhân viên | W35: Kế hoạch - Đấu thầu | X35: Phạm Ngọc Hưng | Y35: Kỹ sư | AA35: duyhai23011992@gmail.com | AB35: 44494 | AC35: 44555 | AD35: 03/01/2022 | AE35: =DATEDIF(AC35,$BF$2,"y") -> 4 | AF35: =VLOOKUP(C35,'[1]T03.2024'!$B$8:$O$58,14,0) -> T01/2022 | AG35: 02/HĐLĐ/2022/TP | AH35: CT | AP35: 7916077355 | AQ35: 5682000 | BG35: 39
A36: =SUBTOTAL(3,$C$3:C36) -> 34 | B36: MS00070 | C36: Nguyễn Một Tê | D36: Nam | E36: 21551 | F36: =MONTH(E36) -> 1 | G36: 086059004399 | H36: 09/08/2021 | I36: CTCCSQLHCVTTXH | J36: Ấp Tường Trí, Nhơn Bình, Trà Ôn, Vĩnh Long | O36: 0364177295 | T36: Thủ kho | U36: Thủ kho | V36: Nhân viên | W36: Vật tư - Thiết bị | X36: Phạm Hoàng Em | Y36: không có | AA36: không | AB36: 44525 | AC36: 44555 | AD36: 0 | AE36: =DATEDIF(AC36,$BF$2,"y") -> 4 | AH36: CT | AP36: 0 | AT36: Không đóng BHXH | BG36: 40
A37: =SUBTOTAL(3,$C$3:C37) -> 35 | B37: MS00080 | C37: Lê Văn Thịnh | D37: Nam | E37: 33544 | F37: =MONTH(E37) -> 11 | G37: 051091002104 | H37: 22/04/2021 | I37: CTCCSQLHCVTTXH | J37: TDP1, Nguyễn Nghiêm, tx Đức Phổ, Quảng Ngãi | K37: Ấp Mỹ Huề | L37: Trung chánh | M37: Hóc Môn | N37: HCM | O37: 0909576598 | Q37: Lê Văn Vương | R37: Anh | S37: 0903155249 | T37: Kỹ sư xây dựng công trình giao thông | U37: Cán bộ kỹ thuật | V37: Nhân viên | W37: Kỹ thuật - Thi công | X37: Nguyễn Thành Trung | Y37: Kỹ sư | AA37: Vanthinh33d6@gmail.com | AB37: 44704 | AC37: 23/07/2022 | AD37: 44805 | AE37: =DATEDIF(AC37,$BF$2,"y") -> 4 | AF37: =VLOOKUP(C37,'[1]T03.2024'!$B$8:$O$58,14,0) -> T09/2022 | AG37: 09/HĐLĐ/2022/TP | AH37: CT | AP37: 7916367294 | AQ37: 5682000 | BG37: 42
A38: =SUBTOTAL(3,$C$3:C38) -> 36 | B38: MS00081 | C38: Nguyễn Ngọc Quý | D38: Nam | E38: 34103 | F38: =MONTH(E38) -> 5 | G38: 074093000539 | H38: 07/04/2021 | I38: CTCCSQLHCVTTXH | J38: Ấp Xóm Lẫm, xã Thanh Tuyền, huyện Dầu Tiếng, tỉnh Bình Dương | K38: Ấp Xóm Lẫm | L38: Xã Thanh Tuyền | M38: Huyện Dầu Tiếng | N38: Tỉnh Bình Dương | O38: 0877603149 | Q38: Nguyễn Thị Ánh Ngọc | R38: Chị gái | S38: 0373528928 | T38: Kỹ thuật trắc địa | U38: Cán bộ kỹ thuật | V38: Nhân viên | W38: Kỹ thuật - Thi công | X38: Nguyễn Thành Trung | Y38: Kỹ sư | AA38: nguyenngocquy.ngngq@gmail.com | AB38: 44705 | AC38: 24/07/2022 | AD38: 44766 | AE38: =DATEDIF(AC38,$BF$2,"y") -> 4 | AF38: =VLOOKUP(C38,'[1]T03.2024'!$B$8:$O$58,14,0) -> T08/2022 | AG38: 10/HĐLĐ/2022/TP | AH38: CT | AP38: 7424616908 | AQ38: 5682000 | BG38: 43
A39: =SUBTOTAL(3,$C$3:C39) -> 37 | B39: MS00036 | C39: Lưu Văn Lưỡng | D39: Nam | E39: 21186 | F39: =MONTH(E39) -> 1 | G39: 086058000949 | H39: 44312 | I39: CTCCSQLHCVTTXH | J39: Ấp Hồi Trinh, Xuân Hiệp, Trà Ôn, Vĩnh Long | K39: 220/91 Lê Văn Sỹ | L39: 14 | M39: 3 | N39: Hồ Chí Minh | O39: 0989668434 | R39: Vợ | S39: 0342397660 | T39: Thủ kho | U39: Thủ kho | V39: Nhân viên | W39: Vật tư - Thiết bị | X39: Dương Thái Luyến | Y39: không có | AB39: 44767 | AC39: 44767 | AD39: 44805 | AE39: =DATEDIF(AC39,$BF$2,"y") -> 4 | AF39: =VLOOKUP(C39,'[1]T03.2024'!$B$8:$O$58,14,0) -> T09/2022 | AG39: 11/HĐLĐ/2022/TP | AH39: CT | AP39: 8622069412 | AQ39: 5682000 | BG39: 46
A40: =SUBTOTAL(3,$C$3:C40) -> 38 | B40: MS00098 | C40: Nguyễn Tuấn Anh | D40: Nam | E40: 26172 | F40: =MONTH(E40) -> 8 | G40: 079071009710 | H40: 44345 | I40: CTCCSQLHCVTTXH | J40: Tân Long, Châu Pha, Thị xã Phú Mỹ, Bà Rịa Vũng Tàu | O40: 0786661971 | Q40: Tran Thi My Hanh | R40: Vợ | S40: 0931116752 | T40: Xây dựng | U40: Cán bộ kỹ thuật | V40: Nhân viên | W40: Kỹ thuật - Thi công | X40: Âu Văn Vũ | Y40: 12/12 | AA40: nguyentuananh471@gmail.com | AB40: 45049 | AC40: 45110 | AD40: 45110 | AE40: =DATEDIF(AC40,$BF$2,"y") -> 3 | AF40: =VLOOKUP(C40,'[1]T03.2024'!$B$8:$O$58,14,0) -> T07/2023 | AG40: 08/HĐLĐ/2023/TP | AH40: CT | AP40: 7931911271 | AQ40: 5682000 | BG40: 50
...

Sheet Nghỉ việc
A2: 1 | B2: =A2+1 -> 2 | C2: =B2+1 -> 3 | D2: =C2+1 -> 4 | E2: =D2+1 -> 5 | F2: =E2+1 -> 6 | G2: =F2+1 -> 7 | H2: =G2+1 -> 8 | I2: =H2+1 -> 9 | ... BG2: =BF2+1 -> 59
A3: Stt | B3: Mã số | C3: Họ và tên | D3: Giới tính | E3: Ngày tháng năm sinh | F3: Tháng sinh nhật | G3: CCCD | H3: Ngày cấp CCCD | I3: Nơi cấp CCCD | J3: Địa chỉ thường trú (ghi theo trên CMND/CCCD) | K3: Địa chỉ tạm trú (nơi đang ở hiện tại) | O3: Số điện thoại liên lạc | P3: Tình trạng hôn nhân | Q3: Họ tên người liên hệ khẩn cấp | R3: Mối quan hệ | S3: Số điện thoại người thân | T3: Nghề nghiệp | U3: Vị trí | V3: Cấp bậc | W3: Phòng ban | X3: Quản lý trực tiếp | Y3: Bằng cấp chuyên môn/ Trình độ văn hóa cao nhất | Z3: Chuyên ngành | AA3: Địa chỉ email (nếu có) | AB3: Ngày nhận việc | AC3: ngày chính thức | AD3: ngày ký hợp đồng | AE3: Thâm niên làm việc | AF3: Tháng đóng BHXH | AG3: Số HĐLĐ cũ | AH3: Trạng thái HĐ | AI3: Ngày ký HĐTV | AJ3: Ngày kết thúc HĐTV | AK3: Ngày ký HĐLĐ XĐTH Lần 1 | AL3: Ngày kết thúc HĐLĐ XĐTH Lần 1 | AM3: Ngày ký HĐLĐ XĐTH Lần 2 | AN3: Ngày kết thúc HĐLĐ XĐTH Lần 2 | AO3: Ngày ký HĐLĐ KXĐTH | AP3: Số sổ BHXH | AQ3: Mức đóng BHXH trên HĐLĐ cũ | AR3: Mức đóng BHXH Từ ngày …./.../…. | AS3: Số TK cá nhân | AT3: Ghi chú | AU3: Mức lương gross Thử việc | AV3: Mức lương gross Chính thức | AW3: Phụ cấp (nếu có) | AX3: Mức lương điều chỉnh tăng lần 1 | AY3: Ngày hiệu lực | AZ3: Mức lương điều chỉnh tăng lần 2 | BA3: Ngày hiệu lực | BB3: Mức lương điều chỉnh tăng lần 3 | BC3: Ngày hiệu lực | BD3: Mức lương gross hiện tại | BE3: Ngày hiệu lực | BF3: Ngày nghỉ việc | BG3: Lý do nghỉ
K4: Số nhà/ Đường | L4: Phường/ Xã | M4: Quận/ Huyện | N4: Thành phố/ Tỉnh
A5: =SUBTOTAL(3,$C$5:C5) -> 0 | C5: Lư Đình Trọng | D5: Nam | BF5: 44214
A6: =SUBTOTAL(3,$C$5:C6) -> 0 | C6: Nguyễn Phương Khánh | D6: Nam | BF6: 44198
A7: =SUBTOTAL(3,$C$5:C7) -> 0 | C7: Huỳnh Văn Tân | D7: Nam | W7: Kế hoạch - Đấu thầu | BF7: 44234
A8: =SUBTOTAL(3,$C$5:C8) -> 0 | C8: Phạm Văn Đuốc | D8: Nam | BF8: 44234
A9: =SUBTOTAL(3,$C$5:C9) -> 0 | C9: Nguyễn Thị Ngọc Mỹ | D9: Nữ | W9: Tài Chính - Kế Toán | BF9: 44234
A10: =SUBTOTAL(3,$C$5:C10) -> 0 | C10: Lê Quốc Bảo | D10: Nam | BF10: 44231
A11: =SUBTOTAL(3,$C$5:C11) -> 0 | C11: Nguyễn Văn Khoa | D11: Nam | U11: QA-QC | W11: Kỹ thuật - Thi công | BF11: 44234
A12: =SUBTOTAL(3,$C$5:C12) -> 0 | C12: Lý Hoàng Duyên | D12: Nam | W12: Kỹ thuật - Thi công | BF12: 44256
A13: =SUBTOTAL(3,$C$5:C13) -> 0 | C13: Lê Minh Hoàng | D13: Nam | U13: CBKT | W13: Kỹ thuật - Thi công | BF13: 44234
A14: =SUBTOTAL(3,$C$5:C14) -> 0 | C14: Nguyễn Minh Đức | D14: Nam | BF14: 44256
A15: =SUBTOTAL(3,$C$5:C15) -> 0 | C15: Huỳnh Minh Nghị | D15: Nam | U15: M&E | W15: Kỹ thuật - Thi công | BF15: 44256
A16: =SUBTOTAL(3,$C$5:C16) -> 0 | C16: Trần Ngọc Đức | D16: Nam | BF16: 44300
A17: =SUBTOTAL(3,$C$5:C17) -> 0 | C17: Nguyễn Văn Nuôi | D17: Nam | BF17: 44348
A18: =SUBTOTAL(3,$C$5:C18) -> 0 | C18: Lê Hoàng Duy | D18: Nam | E18: 33251 | G18: 381626370 | J18: Ấp Hòa Đông- Xã Hòa Tân - Tp Cà Mau - tỉnh Cà Mau | K18: 165 tổ 9, Ấp Tường Nhơn B | L18: Xã Tường Lộc | M18: Huyện Tam Bình | N18: Tỉnh Vĩnh Long | O18: 0938576867 | R18: Mẹ | S18: 0942294272 | U18: CBKT | W18: Kỹ thuật - Thi công | X18: PHẠM HỒNG NHIÊN | Y18: Kỹ sư xây dựng | AA18: lehoangduy568@gmail.com | AB18: 43913 | AP18: 9621258686 | BF18: 44470
A19: =SUBTOTAL(3,$C$5:C19) -> 0 | C19: Lê Thị Diễm Phúc | D19: Nữ | U19: Nhân viên vật tư thiết bị | W19: Vật Tư - Thiết Bị | BF19: 44564
A20: =SUBTOTAL(3,$C$5:C20) -> 0 | C20: Nguyễn Văn Hoa | D20: Nam | U20: CBKT nhôm kính | W20: Kỹ thuật - Thi công | BF20: 44391
A21: =SUBTOTAL(3,$C$5:C21) -> 0 | C21: Nguyễn Thiện Tâm | D21: Nam | E21: 33424 | G21: 321550105 | J21: Ấp Tân Long 2. Xã Tân Thành Bình. Huyện Mỏ Cày Bắc. Bến Tre | K21: 95-97 bình lợi. P13. Quận Bình Thạnh. HCM | L21: P.13 | M21: Bình thạnh | N21: Hồ Chí Minh | O21: 0915532240 | Q21: Nguyễn Kim Ngân | R21: Em gái | S21: 0902979136 | U21: Nhân viên vật tư thiết bị | W21: Vật Tư - Thiết Bị | X21: Vật tư thiêt bị | Y21: Đại học | AB21: 44091 | AP21: 8323017818 | BF21: 44470
A22: =SUBTOTAL(3,$C$5:C22) -> 0 | C22: Phạm Hoàng Minh | D22: Nam | E22: 32030 | G22: 363720493 | J22: Tân Bình, Phụng Hiệp, Hậu Giang | K22: 293B | L22: Phường Mỹ Hoà | M22: Tp. Long Xuyên | N22: An Giang | O22: 0939191089 | U22: Thủ kho công trình | W22: Vật Tư - Thiết Bị | X22: Âu Văn Vũ | Y22: 12/12 | AP22: 9321305224 | BF22: không làm QĐNV
A23: =SUBTOTAL(3,$C$5:C23) -> 0 | C23: Trịnh Phú Quang | D23: Nam | E23: 29452 | G23: 212032070 | H23: 42949 | I23: Công An Quãng Ngãi | J23: Xã Bình Trung - huyện Bình Sơn - tỉnh Quảng Ngãi | K23: 22A Vũ Ngọc Phan | L23: Phường 13 | M23: Quận Bình Thạnh | N23: Hồ Chí Minh | O23: 0383664868 | R23: Người nhà | S23: 0784170676 | U23: Nhân viên Trắc đạc | W23: Kỹ thuật - Thi công | X23: CBKT | Y23: 12/12; CAO ĐẲNG CÔNG NGHỆ KT TRẮC ĐỊA | AB23: 43711 | AP23: 5110002975 | BF23: 44531
A24: =SUBTOTAL(3,$C$5:C24) -> 0 | C24: Nguyễn Thanh Vũ | D24: Nam | E24: 32665 | G24: 086089001173 | H24: 44303 | I24: CTCCSQLHCVTTXH | J24: Ấp An Phú , Xã An Khánh, Huyện Châu Thành, Tỉnh Đồng Tháp | K24: Ấp An Phú, Xã An Khánh, Huyện Châu Thành, Tỉnh Đồng Tháp | L24: Xã An Khánh | M24: Châu Thành | N24: Đồng Tháp | O24: 0778194025 | Q24: Lê Thị Kiều | R24: Vợ | S24: 0985420973 | U24: Kĩ sư xây dựng | W24: Kỹ thuật - Thi công | X24: Âu Văn Vũ | Y24: Kĩ sư xây dựng | AA24: thanhvu6689@gmail.com | AB24: 43907 | AP24: 8621245422 | BF24: 44531
A25: =SUBTOTAL(3,$C$5:C25) -> 0 | C25: Lưu Văn Lưỡng | D25: Nam | E25: 21186 | G25: 086058000949 | H25: 44312 | I25: Công An Vĩnh Long | J25: Ấp Hồi Trinh, Xuân Hiệp, Trà Ôn, Vĩnh Long | K25: 220/91 Lê Văn Sỹ | L25: 14 | M25: 3 | N25: Hồ Chí Minh | O25: 0702985152 | R25: Vợ | S25: 0342397660 | U25: Thủ kho | W25: Vật Tư - Thiết Bị | X25: Võ Thành Vương | AP25: 8622069412 | BF25: 44531
A26: =SUBTOTAL(3,$C$5:C26) -> 0 | C26: Nguyễn Thị Thu Trinh | D26: Nữ | U26: Nhân viên HCNS | W26: Hành chính - Nhân sự | BF26: 44494
A27: =SUBTOTAL(3,$C$5:C27) -> 0 | C27: Nguyễn Văn Út | D27: Nam | E27: 21916 | G27: 330987241 | H27: 39064 | I27: Công An Vĩnh Long | J27: Ấp Phú Sơn C, xã Long Phú, huyện Tam Bình, Vĩnh Long | K27: Ấp Tây | L27: phường Vĩnh Phú | M27: thị xã Thuận An | N27: Bình Dương | O27: 0785648736 | U27: Thủ kho kiêm bảo vệ | W27: Vật Tư - Thiết Bị | X27: Võ Thành Vương | AB27: 44491 | BF27: 44568
A28: =SUBTOTAL(3,$C$5:C28) -> 0 | C28: Nguyễn Trọng Tuấn | D28: Nam | E28: 30020 | G28: 077082001593 | H28: 43439 | I28: CTCCSQLHCVTTXH | J28: Trung Thành, Quảng Thành Châu Đức, Bà Rịa - Vũng Tàu | U28: Phó Giám Đốc Xây Dựng | W28: Kỹ thuật - Thi công | AB28: 43739
A29: =SUBTOTAL(3,$C$5:C29) -> 0 | C29: Nguyễn Văn Nga | D29: Nam | E29: 22883 | G29: 42062001990 | H29: 44305 | I29: CTCCSQLHCVTTXH | J29: 91/15 Bình Lợi, P 13 , Bình Thạnh, Hồ Chí Minh | K29: 91/15 bình lợi | L29: 13 | M29: Bình thạnh | N29: Hồ Chí Minh | O29: 0913445377 | Q29: Phạm thị Thanh Tuyền | R29: Vợ | S29: 0983525377 | U29: Trưởng bộ phận Vật tư Thiết bị | W29: Vật Tư - Thiết Bị | X29: Phạm Hoàng Em | Y29: Kỉ sư CK , Đại học | AA29: nguyenvannga02071960@gmail.com | AB29: 44501 | BF29: 44582
A30: =SUBTOTAL(3,$C$5:C30) -> 0 | C30: Phạm Hồng Nhiên | D30: Nam | E30: 30002 | G30: 054082000089 | H30: 44387 | I30: CTCCSQLHCVTTXH | J30: 47/30/10 Trường Lưu, Long Trường, Q.9, TP.HCM | K30: 47/30/10 Trường Lưu | L30: Phường Long Trường | M30: Tp. Thủ Đức | N30: Hồ Chí Minh | O30: 0916072107 | Q30: Lê Thúy Kim | R30: Vợ | S30: 0909236170 | U30: kỹ sư xây dựng | W30: Kỹ thuật - Thi công | X30: anh Thiện | Y30: Kỹ sư xây dựng | AA30: nhienpham82@gmail.com | AP30: 7912096653 | BF30: 44587
A31: =SUBTOTAL(3,$C$5:C31) -> 0 | B31: MS00072 | C31: Nguyễn Văn Việt | D31: Nam | E31: 34285 | G31: 352133669 | H31: 10/06/2016 | I31: CA An Giang | J31: Tổ 8, ấp Vĩnh Phú, xã Vĩnh An, huyện Châu Thành, tỉnh An Giang | K31: 422 Đào Trí | L31: Phú Thuận | M31: Quận 7 | N31: Hồ Chí Minh | O31: 0343285284 | Q31: Nguyễn thị kim loan | R31: Chị gái | S31: 0986100237 | U31: Kỹ Sư Trắc Đạc | W31: Kỹ thuật - Thi công | X31: Âu Văn Vũ | Y31: Cao đẳng | AA31: Nguyenvietqldd@gmail.com | AB31: 44610 | BF31: 44640
A32: =SUBTOTAL(3,$C$5:C32) -> 0 | C32: Phạm Ngọc Hưng | D32: Nam | E32: 32375 | G32: 215014476 | H32: 43054 | I32: Công An Bình Định | J32: Cát Hanh, Phù Cát, Bình Định | K32: 29/11A đường 48 | L32: Phường Hiệp Bình Chánh | M32: Tp. Thủ Đức | N32: Hồ Chí Minh | O32: 9.7645777e+08 | Q32: Nguyễn Thị Thu Trinh | R32: Vợ | S32: 0938466126 | U32: Trưởng phòng Kế hoạch - Đấu thầu | W32: Kế hoạch - Đấu thầu | X32: Anh Nguyễn Hiếu Thiện | Y32: Kỹ sư xây xựng | AA32: hungngocks2000@gmail.com | AB32: 43545 | AP32: 7910384760 | BF32: 44680
A33: =SUBTOTAL(3,$C$5:C33) -> 0 | B33: MS00077 | C33: Phạm Xuân Hòa | D33: Nam | E33: 32635 | G33: 038089018535 | H33: 43880 | I33: CTCCSQLHCVTTXH | J33: Xã Định Hưng, huyện Yên Định, tỉnh Thanh Hóa | K33: 6B3 Hà Huy Giáp | L33: Thạnh Lộc | M33: Quận 12 | N33: Hồ Chí Minh | O33: 0978546864 | Q33: Trịnh Thị Loan | R33: Mẹ | S33: 01669502350 | U33: Cán Bộ Kỹ Thuật | W33: Kỹ thuật - Thi công | X33: A Trung | Y33: Cao đẳng | AA33: hoathan19892012@gmail.com | AB33: 44652 | BF33: 44658
A34: =SUBTOTAL(3,$C$5:C34) -> 0 | B34: MS00074 | C34: Nguyễn Hoàng Vịnh | D34: Nam | E34: 33903 | G34: 54092001756 | H34: 44313 | I34: CA Phú Yên | J34: Phú Lộc, Hòa Thắng, Phú Hòa, Phú Yên | K34: 106/7B Trương Văn Thành | L34: Phường Hiệp Phú | M34: Tp Thủ Đức | N34: Hồ Chí Minh | O34: 0909111431 | Q34: 0967878160 Chị gái | R34: 0918417547 Em gái | S34: 03299119652 Vợ | U34: Cán Bộ Kỹ Thuật | W34: Kỹ thuật - Thi công | X34: Âu Văn Vũ | Y34: Đại học | AA34: nguyenhoangvinh0078@gmail.com | AB34: 44624 | BF34: 44672
A35: =SUBTOTAL(3,$C$5:C35) -> 0 | B35: MS00076 | C35: Nguyễn Thái Trung | D35: Nam | E35: 34176 | G35: 221335598 | H35: 41572 | I35: CA Phú Yên | J35: Định trung 1 - An Định - Tuy An - Phú Yên | K35: Định trung 1 | L35: An định | M35: Tuy an | N35: Phú yên | O35: 0966442607 | Q35: Nguyễn thái nguyên | R35: Anh ruột | S35: 0973201734 | U35: Cán Bộ Kỹ Thuật | W35: Kỹ thuật - Thi công | X35: Vũ | Y35: Cao đẳng | AA35: Thaitrung260793@gmail.com | AB35: 44641 | BF35: 44673
A36: =SUBTOTAL(3,$C$5:C36) -> 0 | B36: MS00073 | C36: Phạm Đình | D36: Nam | E36: 34566 | G36: 212378162 | H36: 06/02/2015 | I36: CA Tỉnh Quảng Ngãi | J36: Đội 2 thôn Phú Bình Xã Tịnh châu TP Quảng Ngãi Tỉnh Quảng Ngãi | K36: 46/1B Đường 61 | L36: Phước Long B | M36: TP. Thủ Đức | N36: TP HCM | O36: 0961433691 | R36: Vợ | S36: 0922179279 | U36: Cán Bộ Kỹ Thuật | W36: Kỹ thuật - Thi công | X36: A Trung | Y36: Đại học | AA36: phamdinhohin@gmail.com | AB36: 44621 | AP36: 5120139135 | BF36: 44685
A37: =SUBTOTAL(3,$C$5:C37) -> 0 | C37: Võ Thành Vương | D37: Nam | E37: 34099 | G37: 221357413 | H37: 40473 | I37: Công An Phú Yên | J37: Thôn Vĩnh Xuân, xã Hoà Tân Đông, Thị Xã Đông Hoà, Tỉnh Phú Yên | K37: 255/18/4 Quốc Lộ 13 cũ | L37: Hiệp Bình Phước | M37: Tp. Thủ Đức | N37: Hồ Chí Minh | O37: 0336765610 | Q37: Võ Thị Thanh Vương | R37: Vợ | S37: 0334689881 | U37: Kỹ sư xây dựng | W37: Kỹ thuật - Thi công | X37: Nguyễn Hiếu Thiện | Y37: Kỹ sư xây dựng | AA37: vothanhvuongxd@gmail.com | AP37: 7916567172 | BF37: 44680
A38: =SUBTOTAL(3,$C$5:C38) -> 0 | B38: MS00079 | C38: Đỗ Văn Kiên | D38: Nam | E38: 30/05/1987 | G38: 172904258 | H38: 16/02/2016 | I38: Công An Thanh Hóa | J38: Thị Trấn Sao Vàng, huyện Thọ Xuân, tỉnh Thanh Hoá | K38: 13/1 đường số 4, Khu Phố 3 | L38: Linh Xuân | M38: TP Thủ Đức | N38: TP Thủ Đức | O38: 0975997806, 0877757345 | Q38: Đỗ thị hằng | R38: Em gái | S38: 0986696454 | U38: Nhân viên lái máy đào | W38: Vật Tư - Thiết Bị | X38: Dương Thái Luyến | Y38: Trung cấp nghề | AA38: Dovankien69@gmail.com | AB38: 44690 | BF38: 44730
A39: =SUBTOTAL(3,$C$5:C39) -> 0 | B39: MS00082 | C39: Nhữ Văn Thành | D39: Nam | E39: 30176 | G39: 038082014910 | H39: 44460 | I39: CA Thanh Hóa | J39: Thôn Kéo, Điền Trung, Bá Thước, Thanh Hóa | K39: 102 Nguyễn Văn Tạo, ấp 3 | L39: Long Thới | M39: Nhà Bè | N39: Tp. Hồ Chí Minh | O39: 0973196949 | Q39: Lò Thị Hà | R39: Vợ | S39: 0985896225 | U39: Nhân viên kỹ thuật hiện trường | W39: Kỹ thuật - Thi công | X39: Nguyễn Thành Trung | Y39: Cao Đẳng | AA39: thanhdmk@gmail.com | AB39: 44713 | BF39: 44755
A40: =SUBTOTAL(3,$C$5:C40) -> 0 | B40: MS00090 | C40: Nguyễn Tuấn Kiệt | D40: Nam | E40: 35250 | G40: 079096028494 | H40: 22/12/2021 | I40: CTCCSQLHCVTTXH | J40: Tổ 1 . Ấp 4 . Tân Thạnh Đông . Củ chi . Tphcm | K40: 160/5a Huỳnh Minh Mương. Ấp 4. Tân Thạnh Đông . Củ chi. Tphcm | L40: Tân Thạnh Đông | M40: Củ chi | N40: Tphcm | O40: 0356425493 | Q40: Nguyễn Tuấn Anh | R40: Anh | S40: 0967181446 | U40: Nhân viên | W40: Kỹ thuật - Thi công | X40: Công trường | Y40: Cao Đẳng | AA40: Abcdef147593@gmail.cơm | AB40: 44826 | BF40: 44837
A41: =SUBTOTAL(3,$C$5:C41) -> 0 | B41: MS00088 | C41: Võ Ngọc Tân | D41: Nam | E41: 33535 | J41: Thị trấn Cẩm Xuyên, huyện Cẩm Xuyên, tỉnh Hà Tĩnh | O41: 0868626339 | AB41: 44788 | BF41: 44830
...

Sheet Lay so HDTV & MSNV
A1: LẤY SỐ HỢP ĐỒNG THỬ VIỆC
A2: STT | B2: Năm | C2: MSNV | D2: Họ và tên | E2: Vị trí | F2: Từ ngày | G2: Đến ngày | H2: Mức lương
A3: 1 | B3: 2025 | C3: MS00157 | D3: Bùi Thị Xuân
A4: 2 | B4: 2025 | C4: MS00158 | D4: Trần Thị Thi

Sheet Theo doi rieng HĐTV
H2: Ngưỡng đánh giá hợp đồng | I2: 10
A3: STT | B3: Ký HĐ & đóng BHXH | C3: Họ và tên | D3: Giới | E3: Năm sinh | F3: Vị trí tuyển | G3: Thử việc L1 | H3: Thử việc L2 | I3: Ngày chính thức | J3: Ngày tái ký hợp đồng lần 1 | K3: Lương gộp TV | L3: Lương gộp chính thức | M3: Ghi chú
A4: =IF(C4="","",SUBTOTAL(3,$C$4:C4)) -> 1 | C4: Phạm Văn Phụng | D4: Nam | E4: 1975 | F4: Bảo vệ | G4: 44341 | I4: 44402 | K4: 6000000 | L4: 6000000 | M4: Không ký hđlđ, k đóng BH
A5: =IF(C5="","",SUBTOTAL(3,$C$4:C5)) -> 2 | B5: x | C5: Nguyễn Bảo Ngọc | D5: Nữ | E5: 34539 | F5: Nhân viên HCNS | G5: 44340 | H5: 44473 | I5: 44504 | K5: 8000000 | L5: 10000000
A6: =IF(C6="","",SUBTOTAL(3,$C$4:C6)) -> 3 | B6: x | C6: Lê Quốc Dũng | D6: Nam | E6: 28628 | F6: Thủ kho kiêm bảo vệ | G6: 44487 | I6: 44518 | K6: 6000000 | L6: 7000000 | M6: Kết thúc thử việc trong 1 tháng
A7: =IF(C7="","",SUBTOTAL(3,$C$4:C7)) -> 4 | C7: Nguyễn Văn Út | D7: Nam | E7: 22262 | F7: Thủ kho kiêm bảo vệ | G7: 44491 | H7: 44552 | K7: 6500000 | L7: 8000000 | M7: định lại mức lương sau 2 tháng thử việc
A8: =IF(C8="","",SUBTOTAL(3,$C$4:C8)) -> 5 | B8: x | C8: Nguyễn Duy Hải | D8: Nam | E8: 33626 | F8: CBKT (KS dân dụng) | G8: 44494 | I8: 44555 | K8: 12000000 | L8: 15000000
A9: =IF(C9="","",SUBTOTAL(3,$C$4:C9)) -> 6 | C9: Nguyễn Văn Nga | D9: Nam | E9: 22883 | F9: Trưởng bộ phận thiết bị | G9: 44501 | H9: 44531 | I9: 44562 | K9: 15000000 | M9: Thử việc đến khi có chỉ định mới từ TGĐ
A10: =IF(C10="","",SUBTOTAL(3,$C$4:C10)) -> 7 | C10: Nguyễn Một Tê | D10: Nam | E10: 21551 | F10: Thủ kho kiêm bảo vệ | G10: 44525 | I10: 44555 | K10: 7000000 | L10: 7000000
A11: =IF(C11="","",SUBTOTAL(3,$C$4:C11)) -> 8 | B11: x | C11: Phạm Đức Tân | D11: Nam | E11: 28082 | F11: Tài xế | G11: 44551 | I11: 44582 | K11: 5600000 | L11: 8000000
A12: =IF(C12="","",SUBTOTAL(3,$C$4:C12)) -> 9 | C12: Nguyễn Văn Việt | D12: Nam | E12: 34285 | F12: Kỹ sư trắc đạc | G12: 44610 | I12: 44638 | K12: 16000000 | L12: 20000000 | M12: nghỉ việc từ 20/03/2022
A13: =IF(C13="","",SUBTOTAL(3,$C$4:C13)) -> 10 | C13: Phạm Đình | D13: Nam | E13: 34566 | F13: Kỹ sư cầu đường | G13: 44621 | I13: 44682 | K13: 13600000 | L13: 17000000 | M13: nghỉ việc từ 04/05/2022 vì mức lương bị giảm (mr. trung yêu cầu do k đáp ứng yc công việc)
A14: =IF(C14="","",SUBTOTAL(3,$C$4:C14)) -> 11 | C14: Nguyễn Hoàng Vịnh | D14: Nam | E14: 33903 | F14: Chỉ huy phó | G14: 44624 | I14: 44685 | K14: 14000000 | L14: 16000000 | M14: nghỉ việc từ 21/04/2022
A15: =IF(C15="","",SUBTOTAL(3,$C$4:C15)) -> 12 | B15: x | C15: Tô Văn Thành Vương | D15: Nam | E15: 34502 | F15: Kỹ sư cơ điện | G15: 44627 | I15: 44688 | K15: 14000000 | L15: 18000000 | M15: Tăng BH Phú Đức
A16: =IF(C16="","",SUBTOTAL(3,$C$4:C16)) -> 13 | C16: Nguyễn Thái Trung | D16: Nam | E16: 34176 | F16: Kỹ sư trắc đạc | G16: 44641 | I16: 44672 | K16: 15000000 | L16: 18000000 | M16: nghỉ việc từ 22/4/2022
A17: =IF(C17="","",SUBTOTAL(3,$C$4:C17)) -> 14 | C17: Phạm Xuân Hòa | D17: Nam | E17: 32635 | F17: Kỹ sư cầu đường | G17: 44652 | I17: 44713 | K17: 15000000 | L17: 17000000 | M17: nghỉ việc từ chiều 07/04/2022
A18: =IF(C18="","",SUBTOTAL(3,$C$4:C18)) -> 15 | B18: x | C18: Ngô Điền Trung | D18: Nam | E18: 35116 | F18: Kỹ sư cầu đường | G18: 44684 | I18: 44745 | K18: 9000000 | L18: 12000000
A19: =IF(C19="","",SUBTOTAL(3,$C$4:C19)) -> 16 | C19: Đỗ Văn Kiên | D19: Nam | E19: 31927 | F19: Nhân viên lái máy đào | G19: 44690 | I19: 44721 | K19: 12000000 | L19: 15000000 | M19: OT x1.5
A20: =IF(C20="","",SUBTOTAL(3,$C$4:C20)) -> 17 | B20: x | C20: Lê Văn Thịnh | D20: Nam | E20: 33544 | F20: Kỹ sư cầu đường | G20: 44704 | I20: 44765 | K20: 12000000 | L20: 16000000
A21: =IF(C21="","",SUBTOTAL(3,$C$4:C21)) -> 18 | B21: x | C21: Nguyễn Ngọc Quý | D21: Nam | E21: 34103 | F21: Kỹ sư trắc đạc | G21: 44705 | I21: 44766 | K21: 15500000 | L21: 18000000
A22: =IF(C22="","",SUBTOTAL(3,$C$4:C22)) -> 19 | C22: Nhữ Văn Thành | D22: Nam | E22: 30176 | F22: Kỹ sư cầu đường | G22: 44713 | I22: 44774 | K22: 15000000 | M22: Nghỉ từ 13/07/2022
A23: =IF(C23="","",SUBTOTAL(3,$C$4:C23)) -> 20 | B23: x | C23: Nguyễn Thanh Hải | D23: Nam | E23: 27425 | F23: Nhân viên lái xe tưới nước | I23: 44749 | K23: 8000000 | L23: 9000000
A24: =IF(C24="","",SUBTOTAL(3,$C$4:C24)) -> 21 | B24: x | C24: Lưu Văn Lưỡng | D24: Nam | E24: 21186 | F24: Thủ kho kiêm bảo vệ | I24: 44767 | K24: 8000000 | L24: 9000000
A25: =IF(C25="","",SUBTOTAL(3,$C$4:C25)) -> 22 | B25: x | C25: Lê Trọng Nghĩa | D25: Nam | E25: 34490 | F25: Nhân viên lái máy đào | G25: 44729 | I25: 44790 | K25: 10000000 | L25: 13000000 | M25: OT >=2h phụ cấp 30.000/ ngày
A26: =IF(C26="","",SUBTOTAL(3,$C$4:C26)) -> 23 | C26: Nguyễn Văn Hiệu | D26: Nam | E26: 30159 | F26: Kỹ sư QA/QC | G26: 44743 | I26: 44805 | K26: 16000000 | M26: nghỉ từ 2/7/2022
A27: =IF(C27="","",SUBTOTAL(3,$C$4:C27)) -> 24 | C27: Lê Minh Tiến | D27: Nam | E27: 35845 | F27: Kỹ sư cầu đường | G27: 44756 | I27: 44818 | K27: 10000000 | M27: nghỉ từ 13/08/2022
A28: =IF(C28="","",SUBTOTAL(3,$C$4:C28)) -> 25 | C28: Đoàn Mạnh | D28: Nam | E28: 34125 | F28: Kỹ sư cầu đường | G28: 44760 | I28: 44822 | K28: 15000000 | M28: nghỉ từ 19/07/2022
A29: =IF(C29="","",SUBTOTAL(3,$C$4:C29)) -> 26 | B29: x | C29: Phạm Quang Thái | D29: Nam | E29: 34728 | F29: Kỹ sư cầu đường | G29: 44768 | I29: 44830 | K29: 11500000 | L29: 14000000
A30: =IF(C30="","",SUBTOTAL(3,$C$4:C30)) -> 27 | B30: x | C30: Trịnh Tiến Mạnh | D30: Nam | E30: 32053 | F30: Kỹ sư cầu đường | G30: 44774 | I30: 44835 | K30: 17000000 | L30: 18000000
A31: =IF(C31="","",SUBTOTAL(3,$C$4:C31)) -> 28 | C31: Võ Ngọc Tân | D31: Nam | E31: 33535 | F31: Kỹ thuật hiện trường và hồ sơ | G31: 44788 | I31: 44849 | K31: 12000000 | M31: nghỉ từ 26/09/2022
A32: =IF(C32="","",SUBTOTAL(3,$C$4:C32)) -> 29 | C32: Võ Minh Ngôn | D32: Nam | E32: 31664 | F32: Tài xế văn phòng | G32: 44818 | I32: 44879 | K32: 7200000 | L32: 9000000 | M32: nghỉ từ 19/09/2022
A33: =IF(C33="","",SUBTOTAL(3,$C$4:C33)) -> 30 | C33: Đoàn Nhật Tiến | D33: Nam | E33: 31596 | F33: Tài xế văn phòng | G33: 44825 | I33: 44855 | K33: 7200000 | L33: 9000000 | M33: Nghỉ từ 21/11/2022
A34: =IF(C34="","",SUBTOTAL(3,$C$4:C34)) -> 31 | C34: Nguyễn Tuấn Kiệt | D34: Nam | E34: 35250 | F34: Cán bộ kỹ thuật cầu đường | G34: 44826 | I34: 44856 | K34: 10000000 | M34: nghỉ từ 03/10/2022
A35: =IF(C35="","",SUBTOTAL(3,$C$4:C35)) -> 32 | C35: Trần Quốc Việt | D35: Nam | E35: 34680 | F35: Cán bộ kỹ thuật cầu đường | G35: 44841 | I35: 44902 | K35: 11500000 | M35: không nhận việc
A36: =IF(C36="","",SUBTOTAL(3,$C$4:C36)) -> 33 | B36: x | C36: Võ Tấn Vương | D36: Nam | E36: 32145 | F36: Kỹ sư QA/QC | G36: 44861 | I36: 44861 | L36: 20000000 | M36: đóng BHXH từ tháng 5/2023
A37: =IF(C37="","",SUBTOTAL(3,$C$4:C37)) -> 34 | B37: x | C37: Nguyễn Dũng | D37: Nam | E37: 28864 | F37: Tài xế văn phòng | G37: 44886 | I37: 44916 | K37: 8000000 | L37: 9500000
A38: =IF(C38="","",SUBTOTAL(3,$C$4:C38)) -> 35 | B38: x | C38: Nguyễn Thị Xuân Kiều | D38: Nữ | E38: 32184 | F38: Kế toán trưởng | G38: 44956 | I38: 45015 | K38: 16000000 | L38: 20000000 | M38: nghỉ từ 03/07/2023
A39: =IF(C39="","",SUBTOTAL(3,$C$4:C39)) -> 36 | B39: x | C39: Lý Hoàng Duyên | D39: Nam | E39: 31980 | F39: Cán bộ kỹ thuật | G39: 44998 | I39: 45059 | K39: 18000000
A40: =IF(C40="","",SUBTOTAL(3,$C$4:C40)) -> 37 | C40: Nguyễn Xuân Hữu | D40: Nam | E40: 31439 | F40: Cán bộ an toàn lao động | G40: 45019 | I40: 45080 | K40: 16000000 | M40: Nghỉ từ 10/06/2023
A41: =IF(C41="","",SUBTOTAL(3,$C$4:C41)) -> 38 | B41: từ chối | C41: Nguyễn Văn Út | D41: Nam | E41: 30421 | F41: Bảo vệ | G41: 45040 | I41: 45101 | K41: 10000000 | L41: 10000000
...

Sheet Lay so HDLD
A1: LẤY SỐ HỢP ĐỒNG LAO ĐỘNG
A2: STT | B2: Năm | C2: MSNV | D2: Họ và tên | E2: Vị trí | F2: Từ ngày | G2: Đến ngày | H2: Mức lương
A3: 1 | B3: 2025

Sheet Danh mục HDLD
A2: DANH MỤC HỢP ĐỒNG LAO ĐỘNG
A3: STT | B3: Năm | C3: MSNV | D3: Họ và tên | E3: Từ ngày | F3: Đến ngày | G3: Mức lương | H3: Số HĐLĐ | I3: Loại HĐLĐ
A4: 1 | B4: 2021

Sheet DS Đoàn Viên
A2: BÁO CÁO NHÂN SỰ HẰNG NGÀY
A3: DANH SÁCH ĐOÀN VIÊN (CUỐI 2021)
A4: STT | B4: Họ tên | C4: Năm sinh | E4: Ngày vào làm việc tại đơn vị
C5: Nam | D5: Nữ
A6: 1 | B6: Phạm Hoàng Em | C6: 28990 | E6: =VLOOKUP(B6,'Master List'!C3:G39,4,0) -> 5
A7: 2 | B7: Nguyễn Hiếu Thiện | C7: 26451 | E7: =VLOOKUP(B7,'Master List'!C4:G39,4,0) -> 6
A8: 3 | B8: Phan Hoài Minh | C8: 19737 | E8: =VLOOKUP(B8,'Master List'!C5:G39,4,0) -> #N/A
A9: 4 | B9: Nguyễn Bảo Ngọc | D9: 34539 | E9: =VLOOKUP(B9,'Master List'!C6:G39,4,0) -> 7
A10: 5 | B10: Huỳnh Văn Lũy | C10: 29754 | E10: =VLOOKUP(B10,'Master List'!C6:G39,4,0) -> 6
A11: 6 | B11: Đồng Văn Thạch | C11: 27030 | E11: =VLOOKUP(B11,'Master List'!C7:G39,4,0) -> 1
A12: 7 | B12: Trần Văn Khình | C12: 30944 | E12: =VLOOKUP(B12,'Master List'!C8:G40,4,0) -> 9
A13: 8 | B13: Phạm Thị Phương Thảo | D13: 31770 | E13: =VLOOKUP(B13,'Master List'!C9:G40,4,0) -> #N/A
A14: 9 | B14: Võ Thị Muội | D14: 28756 | E14: =VLOOKUP(B14,'Master List'!C10:G41,4,0) -> 9
A15: 10 | B15: Đặng Hà Đoan Dung | D15: 31273 | E15: =VLOOKUP(B15,'Master List'!C10:G42,4,0) -> 8
A16: 11 | B16: Huỳnh Thị Nhiên | D16: 30399 | E16: =VLOOKUP(B16,'Master List'!C11:G42,4,0) -> 3
A17: 12 | B17: Nguyễn Thành Trung | C17: 30376 | E17: =VLOOKUP(B17,'Master List'!C12:G42,4,0) -> 3
A18: 13 | B18: Nguyễn Thành Nhân | C18: 33626 | E18: =VLOOKUP(B18,'Master List'!C13:G42,4,0) -> 1
A19: 14 | B19: Phan Vũ Thịnh | C19: 32150 | E19: =VLOOKUP(B19,'Master List'!C14:G43,4,0) -> 1
A20: 15 | B20: Lê Minh Hoàng | C20: 32235 | E20: =VLOOKUP(B20,'Master List'!C15:G43,4,0) -> 4
A21: 16 | B21: Huỳnh Ngọc Hùng | C21: 32157 | E21: =VLOOKUP(B21,'Master List'!C16:G44,4,0) -> 1
A22: 17 | B22: Nguyễn Văn Trường | C22: 33336 | E22: =VLOOKUP(B22,'Master List'!C17:G44,4,0) -> 4
A23: 18 | B23: Nguyễn Ngọc Phi Hổ | C23: 29306 | E23: =VLOOKUP(B23,'Master List'!C18:G44,4,0) -> 3
A24: 19 | B24: Nguyễn Quốc Trị | C24: 29901 | E24: =VLOOKUP(B24,'Master List'!C19:G45,4,0) -> 11
A25: 20 | B25: Phạm Văn Vũ | C25: 32212 | E25: =VLOOKUP(B25,'Master List'!C20:G45,4,0) -> #N/A
A26: 21 | B26: Phan Phú Trường | C26: 25329 | E26: =VLOOKUP(B26,'Master List'!C21:G45,4,0) -> 5
A27: 22 | B27: Nguyễn Văn Pha | C27: 29221 | E27: =VLOOKUP(B27,'Master List'!C21:G46,4,0) -> 1
A28: 23 | B28: Dương Huỳnh Tâm Quyên | D28: 31247 | E28: =VLOOKUP(B28,'Master List'!C22:G46,4,0) -> 7
A29: 24 | B29: Dương Thái Luyến | C29: 32428 | E29: =VLOOKUP(B29,'Master List'!C23:G46,4,0) -> 10
A30: 25 | B30: Nguyễn Hoa Linh | D30: 32880 | E30: =VLOOKUP(B30,'Master List'!C24:G46,4,0) -> 1
A31: 26 | B31: Nguyễn Hữu Vương | C31: 34010 | E31: =VLOOKUP(B31,'Master List'!C25:G47,4,0) -> #N/A
A32: 27 | B32: Lê Văn Minh | C32: 31807 | E32: =VLOOKUP(B32,'Master List'!C26:G47,4,0) -> #N/A
A33: 28 | B33: Đoàn Thị Kim Tuyền | D33: 32086 | E33: =VLOOKUP(B33,'Master List'!C26:G47,4,0) -> 11
A34: 29 | B34: Nguyễn Thanh Nam | C34: 34993 | E34: =VLOOKUP(B34,'Master List'!C26:G47,4,0) -> 10
A35: 30 | B35: Huỳnh Long Hồ | C35: 32874 | E35: =VLOOKUP(B35,'Master List'!C27:G47,4,0) -> 1
A36: 31 | B36: Đoàn Văn Thuận | C36: 17899 | E36: =VLOOKUP(B36,'Master List'!C28:G47,4,0) -> #N/A
A37: 32 | B37: Hoàng Tăng Bảo Chánh | C37: 26442 | E37: =VLOOKUP(B37,'Master List'!C29:G47,4,0) -> 5
A38: 33 | B38: Âu Văn Vũ | C38: 32523 | E38: =VLOOKUP(B38,'Master List'!C29:G47,4,0) -> 1
A39: 34 | B39: Nguyễn Văn Trân | C39: 18553 | E39: =VLOOKUP(B39,'Master List'!C30:G47,4,0) -> 10
A40: 35 | B40: Huỳnh Minh Nghị | C40: 32303 | E40: =VLOOKUP(B40,'Master List'!C31:G47,4,0) -> 6
A41: 36 | B41: Phạm Văn Phụng | C41: 27395 | E41: =VLOOKUP(B41,'Master List'!C32:G50,4,0) -> 1
...

Sheet DSTK2021
B1: DANH SÁCH TUYỂN DỤNG MỚI VÀ NGHỈ VIỆC 2021
A2: STT | B2: Họ và tên | C2: Vị trí | D2: Bộ Phận | E2: Ngày vào làm | F2: Ngày nghỉ việc
A3: Nhân viên tuyển dụng mới
A4: 1 | B4: Nguyễn Thiện Tâm | C4: Tài xế | D4: Hành chính nhân sự | E4: 44091
A5: 2 | B5: Lê Minh Hoàng | C5: CBKT | D5: Kỹ thuật - Thi công | E5: 44326
A6: 3 | B6: Phạm Văn Phụng | C6: bảo vệ | D6: Vật tư - Thiết bị | E6: 44341
A7: 4 | B7: Nguyễn Bảo Ngọc | C7: Nhân viên HCNS | D7: Hành chính nhân sự | E7: 44340
A8: 5 | B8: Lê Quốc Dũng | C8: Thủ kho kiêm bảo vệ | D8: Vật tư - Thiết bị | E8: 44487
A9: 6 | B9: Nguyễn Văn Út | C9: Thủ kho kiêm bảo vệ | D9: Vật tư - Thiết bị | E9: 44491
A10: 7 | B10: Nguyễn Duy Hải | C10: CBKT | D10: Kỹ thuật - Thi công | E10: 44494
A11: 8 | B11: Nguyễn Văn Nga | C11: Trưởng BPTB | D11: Vật tư - Thiết bị | E11: 44501
A12: 9 | B12: Nguyễn Một Tê | C12: Thủ kho kiêm bảo vệ | D12: Vật tư - Thiết bị | E12: 44525
A13: 10 | B13: Phạm Đức Tân | C13: Tài xế | D13: Hành chính nhân sự | E13: 44551
A14: Nhân viên nghỉ việc
A15: 1 | B15: Lư Đình Trọng | F15: 44214
A16: 2 | B16: Nguyễn Phương Khánh | F16: 44198
A17: 3 | B17: Huỳnh Văn Tân | D17: Đấu thầu | F17: 44234
A18: 4 | B18: Phạm Văn Đuốc | F18: 44234
A19: 5 | B19: Nguyễn Thị Ngọc Mỹ | D19: Kế toán | F19: 44234
A20: 6 | B20: Lê Quốc Bảo | F20: 44231
A21: 7 | B21: Nguyễn Văn Khoa | C21: QA-QC | D21: KTTC | F21: 44234
A22: 8 | B22: Lý Hoàng Duyên | F22: 44256
A23: 9 | B23: Lê Minh Hoàng | C23: CBKT | D23: Kỹ thuật - Thi công | F23: 44234
A24: 10 | B24: Nguyễn Minh Đức | F24: 44256
A25: 11 | B25: Huỳnh Minh Nghị | C25: M&E | D25: Kỹ thuật - Thi công | F25: 44256
A26: 12 | B26: Trần Ngọc Đức | F26: 44300
A27: 13 | B27: Nguyễn Văn Nuôi | F27: 44348
A28: 14 | B28: Lê Hoàng Duy | C28: CBKT | D28: Phòng Kỹ Thuật - Thi Công | F28: 44470
A29: 15 | B29: Lê Thị Diễm Phúc | C29: Nhân viên vật tư thiết bị | D29: Phòng Vật Tư - Thiết Bị | F29: 44564
A30: 16 | B30: Nguyễn Văn Hoa | C30: CBKT | D30: Kỹ thuật - Thi công | F30: 44391
A31: 17 | B31: Nguyễn Thiện Tâm | C31: Nhân viên vật tư thiết bị | D31: Phòng Vật Tư - Thiết Bị | F31: 44470
A32: 18 | B32: Phạm Hoàng Minh | C32: Thủ kho công trình | D32: Phòng Vật Tư - Thiết Bị | F32: không làm QĐNV
A33: 19 | B33: Trịnh Phú Quang | C33: Nhân viên Trắc đạc | D33: Phòng Kỹ Thuật - Thi Công | F33: 44531
A34: 20 | B34: Nguyễn Thanh Vũ | C34: Kĩ sư xây dựng | D34: Phòng Kỹ Thuật - Thi Công | F34: 44531
A35: 21 | B35: Lưu Văn Lưỡng | C35: Thủ kho kiêm bảo vệ | D35: Phòng Vật Tư - Thiết Bị | F35: 44531
A36: 22 | B36: Nguyễn Thị Thu Trinh | C36: Nhân viên HCNS | D36: Hành chính nhân sự | F36: 44494

Sheet DSTK2022
B1: DANH SÁCH TUYỂN DỤNG MỚI VÀ NGHỈ VIỆC 2022
A2: STT | B2: Họ và tên | C2: Vị trí | D2: Bộ Phận | E2: Ngày vào làm | F2: Ngày nghỉ việc
A3: Nhân viên tuyển dụng mới
A4: 1 | B4: Nguyễn Văn Việt | C4: Kỹ sư trắc đạc | D4: KTTC | E4: 44610
A5: 2 | B5: Phạm Đình | C5: Kỹ sư cầu đường | D5: KTTC | E5: 44621
A6: 3 | B6: Nguyễn Hoàng Vịnh | C6: Chỉ huy phó | D6: KTTC | E6: 44624
A7: 4 | B7: Tô Văn Thành Vương | C7: Kỹ sư cơ điện | D7: ME | E7: 44627
A8: 5 | B8: Nguyễn Thái Trung | C8: Kỹ sư trắc đạc | D8: KTTC | E8: 44641
A9: 6 | B9: Phạm Xuân Hòa | C9: Kỹ sư cầu đường | D9: KTTC | E9: 44652
A10: 7 | B10: Ngô Điền Trung | C10: Kỹ sư cầu đường | D10: KTTC | E10: 44684
A11: 8 | B11: Đỗ Văn Kiên | C11: Nhân viên lái máy đào | D11: Thiết bị | E11: 44690
A12: 9 | B12: Lê Văn Thịnh | C12: Kỹ sư cầu đường | D12: KTTC | E12: 44704
A13: 10 | B13: Nguyễn Ngọc Quý | C13: Kỹ sư trắc đạc | D13: KTTC | E13: 44705
A14: 11 | B14: Nhữ Văn Thành | C14: Kỹ sư cầu đường | D14: KTTC | E14: 44713
A15: 12 | B15: Nguyễn Thanh Hải | C15: Nhân viên lái xe tưới nước | D15: Thiết bị | E15: 44749
... A29: 26 | B29: Nguyễn Dũng | C29: Tài xế văn phòng | D29: HCNS | E29: 44886
A30: Nhân viên nghỉ việc
A31: 1 | B31: Nguyễn Văn Việt | C31: Kỹ sư trắc đạc | D31: KTTC | F31: 20/03/2022
A32: 2 | B32: Phạm Đình | C32: Kỹ sư cầu đường | D32: KTTC | F32: 04/05/2022
A33: 3 | B33: Nguyễn Hoàng Vịnh | C33: Chỉ huy phó | D33: KTTC | F33: 21/04/2022
A34: 4 | B34: Nguyễn Thái Trung | C34: Kỹ sư trắc đạc | D34: KTTC | F34: 22/4/2022
A35: 5 | B35: Phạm Xuân Hòa | C35: Kỹ sư cầu đường | D35: KTTC | F35: 07/04/2022
A36: 6 | B36: Đỗ Văn Kiên | C36: Nhân viên lái máy đào | D36: Thiết bị | F36: 44730
A37: 7 | B37: Nhữ Văn Thành | C37: Kỹ sư cầu đường | D37: KTTC | F37: 13/07/2022
A38: 8 | B38: Nguyễn Văn Hiệu | C38: Kỹ sư QA/QC | D38: KTTC | F38: 02/07/2022
A39: 9 | B39: Lê Minh Tiến | C39: Kỹ sư cầu đường | D39: KTTC | F39: 13/08/2022
A40: 10 | B40: Đoàn Mạnh | C40: Kỹ sư cầu đường | D40: KTTC | F40: 19/07/2022
A41: 11 | B41: Võ Ngọc Tân | C41: Kỹ thuật hiện trường và hồ sơ | D41: KTTC | F41: 26/09/2022
A42: 12 | B42: Võ Minh Ngôn | C42: Tài xế văn phòng | D42: HCNS | F42: 19/09/2022
A43: 13 | B43: Đoàn Nhật Tiến | C43: Tài xế văn phòng | D43: HCNS | F43: 21/11/2022
A44: 14 | B44: Nguyễn Tuấn Kiệt | C44: Cán bộ kỹ thuật cầu đường | D44: KTTC | F44: 03/10/2022
A45: 15 | B45: Trần Quốc Việt | C45: Cán bộ kỹ thuật cầu đường | D45: KTTC | F45: không nhận việc
